Workbook

Sheet Sheet1
A1: 请求链接 | B1: 游戏名称 | C1: 发布日期 | D1: 下载量 | E1: 关注量 | F1: 评分 | G1: 评价数量 | H1: 核对
A2: https://www.taptap.cn/app/849542?os=android | B2: 无边星空 | C2: 2026-04-27 | D2: 2497 | E2: 1896 | F2: 7.6 | G2: 55 | H2: =VLOOKUP(A2,[1]游戏清单!$A$2:$A$3064,1,FALSE) -> https://www.taptap.cn/app/849542?os=android
A3: https://www.taptap.cn/app/848627?os=android | B3: 你是哪种傻福？ | C3: 2026-04-24 | D3: 8931 | E3: 8262 | F3: 5.2 | G3: 64 | H3: =VLOOKUP(A3,[1]游戏清单!$A$2:$A$3064,1,FALSE) -> https://www.taptap.cn/app/848627?os=android
A4: https://www.taptap.cn/app/847989?os=android | B4: 捕鱼大亨 | C4: 2026-04-23 | D4: 259 | E4: 229 | F4: 1 | G4: 2 | H4: =VLOOKUP(A4,[1]游戏清单!$A$2:$A$3064,1,FALSE) -> https://www.taptap.cn/app/847989?os=android
A5: https://www.taptap.cn/app/816371?os=android | B5: 装甲新世纪 | C5: 2026-02-06 | D5: 369 | E5: 365 | F5: 1 | G5: 2 | H5: =VLOOKUP(A5,[1]游戏清单!$A$2:$A$3064,1,FALSE) -> https://www.taptap.cn/app/816371?os=android
A6: https://www.taptap.cn/app/849109?os=android | B6: 血之末裔 | C6: 2026-04-28 | D6: 329 | E6: 246 | F6: 9.2 | G6: 7 | H6: =VLOOKUP(A6,[1]游戏清单!$A$2:$A$3064,1,FALSE) -> https://www.taptap.cn/app/849109?os=android
A7: https://www.taptap.cn/app/841899?os=android | B7: 末日生存推演 | C7: 2026-04-13 | D7: 307 | E7: 263 | F7: 5.9 | G7: 7 | H7: =VLOOKUP(A7,[1]游戏清单!$A$2:$A$3064,1,FALSE) -> https://www.taptap.cn/app/841899?os=android
A8: https://www.taptap.cn/app/841429?os=android | B8: 战姬防线 | C8: 2026-04-28 | D8: 5902 | E8: 4785 | F8: 9 | G8: 40 | H8: =VLOOKUP(A8,[1]游戏清单!$A$2:$A$3064,1,FALSE) -> https://www.taptap.cn/app/841429?os=android
A9: https://www.taptap.cn/app/843499?os=android | B9: 放置暗黑传奇 | C9: 2026-04-23 | D9: 6448 | E9: 4945 | F9: 8 | G9: 55 | H9: =VLOOKUP(A9,[1]游戏清单!$A$2:$A$3064,1,FALSE) -> https://www.taptap.cn/app/843499?os=android
A10: https://www.taptap.cn/app/848783?os=android | B10: 一刀999 | C10: 2026-04-25 | D10: 1798 | E10: 1286 | F10: 6.4 | G10: 27 | H10: =VLOOKUP(A10,[1]游戏清单!$A$2:$A$3064,1,FALSE) -> https://www.taptap.cn/app/848783?os=android
A11: https://www.taptap.cn/app/850415?os=android | B11: 菜场大亨 | C11: 2026-04-29 | D11: 3583 | E11: 3099 | F11: 8.3 | G11: 16 | H11: =VLOOKUP(A11,[1]游戏清单!$A$2:$A$3064,1,FALSE) -> https://www.taptap.cn/app/850415?os=android
A12: https://www.taptap.cn/app/846160?os=android | B12: 像素守卫战 | C12: 2026-05-01 | D12: 251 | E12: 216 | F12: 6.2 | G12: 12 | H12: =VLOOKUP(A12,[1]游戏清单!$A$2:$A$3064,1,FALSE) -> https://www.taptap.cn/app/846160?os=android
A13: https://www.taptap.cn/app/820836?os=android | B13: 迷雾庇护所 | C13: 2026-02-24 | D13: 29602 | E13: 26223 | F13: 8.3 | G13: 168 | H13: =VLOOKUP(A13,[1]游戏清单!$A$2:$A$3064,1,FALSE) -> https://www.taptap.cn/app/820836?os=android
... A65: https://www.taptap.cn/app/839176?os=android | B65: 真实人生：模拟生活 | C65: 2026-04-24 | D65: 72722 | E65: 70173 | F65: 7.6 | G65: 406 | H65: =VLOOKUP(A65,[1]游戏清单!$A$2:$A$3064,1,FALSE) -> https://www.taptap.cn/app/839176?os=android
A66: https://www.taptap.cn/app/850502?os=android | B66: 获取失败 | C66: 获取失败 | D66: 获取失败 | E66: 获取失败 | F66: 获取失败 | G66: 获取失败 | H66: =VLOOKUP(A66,[1]游戏清单!$A$2:$A$3064,1,FALSE) -> https://www.taptap.cn/app/850502?os=android
A67: https://www.taptap.cn/app/825688?os=android | B67: 一剑入江湖 | C67: 2026-03-14 | D67: 2156 | E67: 1447 | F67: 6.9 | G67: 36 | H67: =VLOOKUP(A67,[1]游戏清单!$A$2:$A$3064,1,FALSE) -> https://www.taptap.cn/app/825688?os=android
A68: https://www.taptap.cn/app/835416?os=android | B68: 暗黑神破坏 | C68: 2026-04-06 | D68: 2080 | E68: 1546 | F68: 4.1 | G68: 39 | H68: =VLOOKUP(A68,[1]游戏清单!$A$2:$A$3064,1,FALSE) -> https://www.taptap.cn/app/835416?os=android
A69: https://www.taptap.cn/app/835231?os=android | B69: 骰了个骰3D | C69: 2026-03-29 | D69: 63 | E69: 53 | F69: 未找到 | G69: 未找到 | H69: =VLOOKUP(A69,[1]游戏清单!$A$2:$A$3064,1,FALSE) -> https://www.taptap.cn/app/835231?os=android
A70: https://www.taptap.cn/app/842752?os=android | B70: 道觅 | C70: 2026-04-30 | D70: 0 | E70: 78 | F70: 5.7 | G70: 5 | H70: =VLOOKUP(A70,[1]游戏清单!$A$2:$A$3064,1,FALSE) -> https://www.taptap.cn/app/842752?os=android
A71: https://www.taptap.cn/app/838284?os=android | B71: 魔兽城堡：我养成了SS英雄 | C71: 2026-04-14 | D71: 2234 | E71: 1625 | F71: 7.6 | G71: 23 | H71: =VLOOKUP(A71,[1]游戏清单!$A$2:$A$3064,1,FALSE) -> https://www.taptap.cn/app/838284?os=android
A72: https://www.taptap.cn/app/836736?os=android | B72: 系统蛇：代码围城 | C72: 2026-04-03 | D72: 109 | E72: 125 | F72: 1 | G72: 3 | H72: =VLOOKUP(A72,[1]游戏清单!$A$2:$A$3064,1,FALSE) -> https://www.taptap.cn/app/836736?os=android
A73: https://www.taptap.cn/app/838319?os=android | B73: 巅峰征程:电竞人生 | C73: 2026-04-07 | D73: 46707 | E73: 41304 | F73: 8.5 | G73: 124 | H73: =VLOOKUP(A73,[1]游戏清单!$A$2:$A$3064,1,FALSE) -> https://www.taptap.cn/app/838319?os=android
A74: https://www.taptap.cn/app/845402?os=android | B74: 星殖计划 | C74: 2026-04-20 | D74: 4736 | E74: 4034 | F74: 5.8 | G74: 15 | H74: =VLOOKUP(A74,[1]游戏清单!$A$2:$A$3064,1,FALSE) -> https://www.taptap.cn/app/845402?os=android
A75: https://www.taptap.cn/app/839013?os=android | B75: 克苏鲁降临：生物进化 | C75: 2026-04-07 | D75: 28955 | E75: 24834 | F75: 7 | G75: 114 | H75: =VLOOKUP(A75,[1]游戏清单!$A$2:$A$3064,1,FALSE) -> https://www.taptap.cn/app/839013?os=android
A76: https://www.taptap.cn/app/835201?os=android | B76: 丧尸末日：幸存者基地 | C76: 2026-03-28 | D76: 2060 | E76: 1752 | F76: 7.3 | G76: 22 | H76: =VLOOKUP(A76,[1]游戏清单!$A$2:$A$3064,1,FALSE) -> https://www.taptap.cn/app/835201?os=android
A77: https://www.taptap.cn/app/841536?os=android | B77: 斗战三国 | C77: 2026-04-17 | D77: 3352 | E77: 3115 | F77: 9.2 | G77: 10 | H77: =VLOOKUP(A77,[1]游戏清单!$A$2:$A$3064,1,FALSE) -> https://www.taptap.cn/app/841536?os=android
A78: https://www.taptap.cn/app/834893?os=android | B78: 极限堡垒 | C78: 2026-03-29 | D78: 7108 | E78: 5855 | F78: 8.1 | G78: 40 | H78: =VLOOKUP(A78,[1]游戏清单!$A$2:$A$3064,1,FALSE) -> https://www.taptap.cn/app/834893?os=android
A79: https://www.taptap.cn/app/836346?os=android | B79: 纸牌合集 | C79: 2026-03-31 | D79: 1358 | E79: 1313 | F79: 1 | G79: 7 | H79: =VLOOKUP(A79,[1]游戏清单!$A$2:$A$3064,1,FALSE) -> https://www.taptap.cn/app/836346?os=android
A80: https://www.taptap.cn/app/844899?os=android | B80: 末班地铁：无限循环 | C80: 2026-04-28 | D80: 40 | E80: 47 | F80: 1 | G80: 1 | H80: =VLOOKUP(A80,[1]游戏清单!$A$2:$A$3064,1,FALSE) -> https://www.taptap.cn/app/844899?os=android
A81: https://www.taptap.cn/app/831667?os=android | B81: 废土求生 | C81: 2026-03-27 | D81: 129 | E81: 105 | F81: 4.4 | G81: 5 | H81: =VLOOKUP(A81,[1]游戏清单!$A$2:$A$3064,1,FALSE) -> https://www.taptap.cn/app/831667?os=android
... A86: https://www.taptap.cn/app/848858?os=android | B86: 逍遥修仙录 | C86: 2026-04-25 | D86: 425 | E86: 331 | F86: 7.6 | G86: 16 | H86: =VLOOKUP(A86,[1]游戏清单!$A$2:$A$3064,1,FALSE) -> https://www.taptap.cn/app/848858?os=android
A87: https://www.taptap.cn/app/848989?os=android | B87: 末日沙漠生存 | C87: 2026-04-26 | D87: 97 | E87: 98 | F87: 未找到 | G87: 未找到 | H87: =VLOOKUP(A87,[1]游戏清单!$A$2:$A$3064,1,FALSE) -> https://www.taptap.cn/app/848989?os=android
A88: https://www.taptap.cn/app/848539?os=android | B88: 我的战车无限升级 | C88: 2026-04-26 | D88: 4190 | E88: 3512 | F88: 7.5 | G88: 30 | H88: =VLOOKUP(A88,[1]游戏清单!$A$2:$A$3064,1,FALSE) -> https://www.taptap.cn/app/848539?os=android
A89: https://www.taptap.cn/app/841297?os=android | B89: 纪元之战 | C89: 2026-04-12 | D89: 804 | E89: 649 | F89: 7.4 | G89: 11 | H89: =VLOOKUP(A89,[1]游戏清单!$A$2:$A$3064,1,FALSE) -> https://www.taptap.cn/app/841297?os=android
A90: https://www.taptap.cn/app/848937?os=android | B90: 富婆修仙只修法器 | C90: 2026-04-29 | D90: 321 | E90: 246 | F90: 7.6 | G90: 5 | H90: =VLOOKUP(A90,[1]游戏清单!$A$2:$A$3064,1,FALSE) -> https://www.taptap.cn/app/848937?os=android
A91: https://www.taptap.cn/app/835578?os=android | B91: 堆叠纪元：赛博五十日 | C91: 2026-04-15 | D91: 3733 | E91: 3063 | F91: 8 | G91: 26 | H91: =VLOOKUP(A91,[1]游戏清单!$A$2:$A$3064,1,FALSE) -> https://www.taptap.cn/app/835578?os=android
A92: https://www.taptap.cn/app/848846?os=android | B92: 流放之我技能最强 | C92: 2026-04-27 | D92: 3339 | E92: 2555 | F92: 5.5 | G92: 16 | H92: =VLOOKUP(A92,[1]游戏清单!$A$2:$A$3064,1,FALSE) -> https://www.taptap.cn/app/848846?os=android
A93: https://www.taptap.cn/app/850098?os=android | B93: 美国斩杀线 | C93: 2026-04-28 | D93: 463 | E93: 443 | F93: 1 | G93: 1 | H93: =VLOOKUP(A93,[1]游戏清单!$A$2:$A$3064,1,FALSE) -> https://www.taptap.cn/app/850098?os=android
A94: https://www.taptap.cn/app/850666?os=android | B94: 风暴临界点 | C94: 2026-04-30 | D94: 24 | E94: 21 | F94: 未找到 | G94: 未找到 | H94: =VLOOKUP(A94,[1]游戏清单!$A$2:$A$3064,1,FALSE) -> https://www.taptap.cn/app/850666?os=android
A95: https://www.taptap.cn/app/838189?os=android | B95: 江湖录 | C95: 2026-04-07 | D95: 3808 | E95: 2907 | F95: 8.6 | G95: 26 | H95: =VLOOKUP(A95,[1]游戏清单!$A$2:$A$3064,1,FALSE) -> https://www.taptap.cn/app/838189?os=android
...
